File: example/0-150W.vms
VAMAS Surface Chemical Analysis Standard Data Transfer Format 1988 May 4
Not specified
MI-600-BE9240AA
600-72-HP\600-72
Thinfilm_20200827.experiment
0
NORM
REGULAR
1
4
Index
d
PositionX [mm]
n
PositionY [mm]
n
PositionZ [mm]
n
0
0
0
0
5
wide
Ni-W
2020
8
27
14
5
46
7
39
Creation
Created by : 600-72-HP\600-72
Date created : 27/08/2020 14:05
Computer : 600-72-HP
Location
Location ID : 0-150W
Sample : Ni-W
Description : (21.195,11.291,0.905)mm
Tilt : 0.00
Charge Neutraliser : On
Filament Current : 0.45A
Filament Bias : 1V
Charge Balance : 4V
Settings
Excitation
Mode : XPS - monochromatic
Tuning : Spectroscopy
Emission current : 15.00mA
Anode library : Al
ESCA modes
Collimation : Slot
Lens : Hybrid
Resolution : 160.00
Scan
Deflection : (0.000, 0.000)mm
wide : 286.690-1491.690eV, Sweeps 1
Start : 286.690eV
End : 1491.690eV
Centre : 889.190eV
Width : 1205.000eV
Step size : 1.000eV
Number Steps : 1205
Dwell time : 100ms
Sweep time : 120s
Sweeps : 1
Instrument Conditions
Work function : -4.50
Acquisition Conditions
X-ray Power : 225.00W
XPS
1
21.19525
11.290625
0.905375
Al (mono)
1486.69
225
1E+37
1E+37
1E+37
1E+37
FAT
160
1E+37
-4.5
1E+37
1E+37
1E+37
1E+37
1E+37
wide

-1
Kinetic energy
eV
286.69
1
2
Intensity
d
Transmission
d
pulse counting
0.0995024875621891
0
1E+37
0
5
46.6505644502972
2106
2115
2073
2052
2088
2050
2050
2059
2069
2121
2131
2135
2096
2123
2098
2167
2165
2021
2032
2060
2120
2149
2099
2072
2103
2093
2064
2068
2104
2107
2087
2130
2099
2066
2118
2127
2070
2116
2125
2144
2108
2069
2135
2146
2146
2168
2090
2164
2135
2161
2153
2190
2167
2184
2132
2200
2147
2107
2126
2184
2095
2160
2163
2132
2154
2238
2160
2104
2230
2216
2117
2141
2163
2127
2080
2149
2087
2091
2142
2121
2205
2127
2133
2162
2117
2118
2172
2191
2175
2153
2175
2172
2189
2219
2143
2168
2150
2091
2135
2194
2164
2163
2179
2137
2164
2244
2204
2127
2140
2164
2119
2158
2150
2103
2201
2193
2184
2147
2186
2113
2101
2105
2166
2172
2137
2142
2181
2074
2127
2164
2228
2167
2239
2162
2190
2161
2181
2131
2165
2209
2227
2258
2174
2142
2240
2246
2216
2254
2251
2279
2225
2280
2229
2189
2209
2185
2239
2211
2192
2172
2271
2288
2223
2287
2282
2281
2212
2234
2178
2234
2269
2228
2258
2269
2288
2331
2319
2262
2308
2276
2259
2302
2299
2267
2314
2295
2307
2333
2345
2310
2373
2409
2384
2325
2309
2384
2339
2408
2285
2319
2290
2260
2424
2409
2465
2526
2490
2495
2520
2416
2352
2333
2282
2286
2315
2246
2232
2235
2290
2311
2234
2308
2340
2423
2501
2637
2737
2731
2621
2587
2382
2255
2243
2111
2032
2015
1932
1910
1808
1788
1822
1830
1859
1868
1799
1842
1868
1748
1809
1774
1808
1806
1801
1787
1820
1900
1884
1859
1799
1825
1848
1846
1952
1883
1884
1828
1841
1881
1767
1841
1904
1885
1863
1880
1799
1900
1868
1864
1856
1861
1870
1872
1840
1857
1896
1915
1910
1858
1844
1844
1858
1958
1962
1890
1928
1902
1892
1937
1884
1902
1900
1881
1890
1894
1900
1947
1925
1946
1955
1960
1950
1904
1961
1957
1981
1910
1950
1982
1960
2015
1979
1939
1958
1924
1935
1940
1890
1957
1993
1929
2019
1978
1937
1957
1997
1925
1979
2035
1940
2009
1990
1997
1978
1984
1961
2003
2010
1988
1949
1954
1934
1926
1958
1966
1975
1968
2028
2102
2024
2026
2015
1976
1988
1997
1995
1991
2103
2024
1974
2005
2051
1966
2046
2078
2056
2012
2052
2044
2037
2088
2009
2006
2074
2059
2043
2005
2021
2086
2043
2055
2038
2111
2080
2070
2071
2063
2082
2022
2071
2122
2078
2039
2097
2091
2045
2100
2132
2132
2130
2031
2081
2050
2042
2166
2159
2051
2076
2155
2163
2143
2158
2173
2091
2161
2175
2107
2122
2142
2146
2150
2109
2118
2129
2103
2085
2125
2219
2166
2175
2155
2164
2107
2159
2143
2183
2127
2174
2229
2219
2265
2212
2233
2238
2202
2095
2149
2240
2279
2214
2238
2258
2287
2256
2235
2233
2275
2226
2281
2234
2216
2206
2286
2305
2278
2342
2226
2252
2311
2274
2275
2261
2268
2183
2239
2258
2299
2282
2278
2310
2290
2333
2331
2343
2313
2428
2342
2331
2418
2368
2317
2334
2327
2291
2326
2324
2394
2359
2361
2385
2333
2369
2327
2323
2469
2567
2529
2435
2494
2477
2398
2389
2363
2362
2394
2434
2410
2387
2349
2386
2456
2444
2478
2466
2345
2412
2365
2452
2503
2479
2488
2462
2464
2536
2453
2479
2417
2469
2476
2533
2490
2581
2531
2480
2448
2518
2513
2495
2479
2492
2489
2503
2502
2591
2602
2642
2578
2577
2540
2482
2522
2604
2638
2630
2606
2630
2661
2645
2650
2657
2659
2653
2684
2563
2648
2637
2658
2571
2687
2685
2614
2612
2566
2658
2713
2623
2582
2622
2701
2644
2732
2661
2712
2815
2835
2808
2779
2784
2818
2791
2708
2721
2665
2669
2656
2643
2601
2541
2563
2558
2664
2640
2658
2650
2650
2584
2661
2684
2679
2719
2735
2614
2660
2675
2705
2741
2727
2673
2656
2709
2686
2674
2699
2655
2654
2658
2640
2724
2742
2785
2751
2757
2780
2760
2780
2769
2710
2759
2718
2726
2676
2571
2511
2527
2538
2490
2487
2426
2417
2492
2853
3694
5454
6050
3985
2452
2221
2147
2078
2111
2122
2182
2121
2184
2182
2148
2176
2172
2149
2205
2167
2150
2113
2170
2090
2111
2107
2159
2096
2125
2128
2112
2120
2107
2052
2261
2239
2266
2257
2236
2202
2156
2124
2120
2033
2003
1997
2065
2111
1997
1970
2032
2015
1978
1933
1878
2010
1994
2034
1942
2011
2039
2074
2013
2024
1956
1971
1976
1928
1917
2009
2038
1919
2023
2054
1964
1966
2009
2052
1962
1933
1994
1969
1920
1967
2031
1974
2052
2029
1975
1957
1996
2007
2040
1942
1998
1974
1907
1917
1908
2040
2088
2061
2241
2424
2447
2523
2412
2216
2099
1962
1908
1889
1837
1759
1772
1710
1656
1705
1679
1658
1727
1711
1668
1655
1656
1743
1626
1705
1666
1716
1946
1980
1836
1708
1649
1645
1666
1625
1632
1662
1671
1677
1605
1637
1672
1630
1711
1672
1639
1578
1647
1650
1606
1581
1634
1648
1568
1588
1642
1665
1666
1654
1635
1643
1602
1680
1662
1660
1637
1645
1737
1653
1593
1641
1650
1617
1576
1641
1669
1615
1619
1634
1552
1539
1585
1654
1673
1583
1625
1685
1623
1641
1633
1619
1534
1615
1615
1597
1584
1578
1606
1614
1610
1617
1627
1633
1589
1633
1642
1638
1685
1659
1691
1627
1610
1653
1591
1612
1577
1637
1622
1604
1599
1653
1599
1603
1582
1650
1606
1630
1593
1634
1580
1606
1602
1633
1561
1557
1639
1613
1570
1593
1611
1676
1722
1764
1800
2036
2235
1992
1677
1664
1616
1571
1641
1619
1678
1647
1611
1588
1608
1495
1560
1542
1529
1531
1617
1670
1648
1745
1875
2164
2346
2268
1931
1657
1474
1304
1263
1251
1301
1385
1542
1885
2273
2413
2121
1611
1259
1048
884
822
764
660
666
669
627
590
625
595
606
613
598
565
569
570
547
579
588
601
592
564
529
539
538
541
532
580
546
534
571
520
545
532
570
530
528
542
572
538
529
546
539
552
554
528
549
589
566
549
533
558
545
537
517
523
535
511
534
545
595
566
534
563
553
527
542
532
536
511
559
564
536
551
536
561
581
548
522
533
509
518
544
544
550
538
553
528
524
528
546
554
532
492
516
535
563
531
572
510
554
533
549
543
541
512
523
541
525
497
559
546
539
576
589
563
584
574
558
527
543
548
534
532
556
522
533
544
531
537
549
559
541
519
526
574
556
562
563
565
575
576
580
550
536
565
587
549
557
546
572
588
565
578
589
589
554
548
564
560
585
621
600
600
576
546
572
575
547
566
553
564
541
551
552
571
617
622
584
594
610
613
591
617
618
601
560
561
609
617
635
614
616
549
478
423
413
395
441
455
532
560
546
739
1513
2015
2113
2235
1102
229
108
74
80
72
74
65
71
87
94
122
150
130
80
51
45
36
40
32
36
32
31
37
53
83
110
129
130
117
83
40
18
8
8
9
5
9
46.6505644502972
Ni 2p
Ni-W
2020
8
27
14
22
28
7
39
Creation
Created by : 600-72-HP\600-72
Date created : 27/08/2020 14:22
Computer : 600-72-HP
Location
Location ID : 0-150W
Sample : Ni-W
Description : (21.195,11.291,0.905)mm
Tilt : 0.00
Charge Neutraliser : On
Filament Current : 0.45A
Filament Bias : 1V
Charge Balance : 4V
Settings
Excitation
Mode : XPS - monochromatic
Tuning : Spectroscopy
Emission current : 15.00mA
Anode library : Al
ESCA modes
Collimation : Slot
Lens : Hybrid
Resolution : 20.00
Scan
Deflection : (0.000, 0.000)mm
Ni 2p : 586.690-646.690eV, Sweeps 1
Start : 586.690eV
End : 646.690eV
Centre : 616.690eV
Width : 60.000eV
Step size : 0.100eV
Number Steps : 600
Dwell time : 100ms
Sweep time : 60s
Sweeps : 1
Instrument Conditions
Work function : -4.50
Acquisition Conditions
X-ray Power : 225.00W
XPS
2
21.19525
11.290625
0.905375
Al (mono)
1486.69
225
1E+37
1E+37
1E+37
1E+37
FAT
20
1E+37
-4.5
1E+37
1E+37
1E+37
1E+37
1E+37
Ni
2p
-1
Kinetic energy
eV
586.69
0.1
2
Intensity
d
Transmission
d
pulse counting
0.099833
1
0
1E+37
1E+37
1E+37
0
1202
87
144
2.16443894216647
2.16811548515889
114
2.16443894216647
119
2.16444585566695
125
2.16445276916744
122
2.16445968266793
95
2.16446659616842
124
2.1644735096689
108
2.16448042316939
122
2.16448733666988
105
2.16449425017037
125
2.16450116367085
111
2.16450807717134
112
2.16451499067183
109
2.16452190417232
98
2.1645288176728
113
2.16453573117329
109
2.16454264467378
117
2.16454955817427
113
2.16455647167475
112
2.16456338517524
96
2.16457029867573
108
2.16457721217622
112
2.1645841256767
110
2.16459103917719
101
2.16459795267768
114
2.16460486617817
118
2.16461177967865
109
2.16461869317914
102
2.16462560667963
101
2.16463252018012
123
2.16463943368061
105
2.16464634718109
108
2.16465326068158
112
2.16466017418207
118
2.16466708768256
114
2.16467400118304
114
2.16468091468353
101
2.16468782818402
106
2.16469474168451
115
2.16470165518499
108
2.16470856868548
118
2.16471548218597
104
2.16472239568646
116
2.16472930918694
120
2.16473622268743
108
2.16474313618792
106
2.16475004968841
100
2.16475696318889
103
2.16476387668938
95
2.16477079018987
106
2.16477770369036
97
2.16478461719084
114
2.16479153069133
103
2.16479844419182
115
2.16480535769231
114
2.16481227119279
111
2.16481918469328
118
2.16482609819377
103
2.16483301169426
103
2.16483992519474
103
2.16484683869523
102
2.16485375219572
99
2.16486066569621
111
2.16486757919669
119
2.16487449269718
132
2.16488140619767
118
2.16488831969816
109
2.16489523319864
115
2.16490214669913
112
2.16490906019962
102
2.16491597370011
103
2.16492288720059
119
2.16492980070108
123
2.16493671420157
102
2.16494362770206
93
2.16495054120254
100
2.16495745470303
115
2.16496436820352
92
2.16497128170401
113
2.16497819520449
109
2.16498510870498
108
2.16499202220547
106
2.16499893570596
124
2.16500584920644
115
2.16501276270693
103
2.16501967620742
104
2.16502658970791
100
2.16503350320839
115
2.16504041670888
109
2.16504733020937
102
2.16505424370986
119
2.16506115721034
117
2.16506807071083
98
2.16507498421132
96
2.16508189771181
103
2.16508881121229
104
2.16509572471278
108
2.16510263821327
99
2.16510955171376
119
2.16511646521424
101
2.16512337871473
107
2.16513029221522
111
2.16513720571571
108
2.16514411921619
129
2.16515103271668
121
2.16515794621717
109
2.16516485971766
102
2.16517177321814
116
2.16517868671863
115
2.16518560021912
123
2.16519251371961
115
2.16519942722009
118
2.16520634072058
116
2.16521325422107
99
2.16522016772156
115
2.16522708122204
111
2.16523399472253
114
2.16524090822302
109
2.16524782172351
111
2.16525473522399
119
2.16526164872448
115
2.16526856222497
114
2.16527547572546
102
2.16528238922594
108
2.16528930272643
107
2.16529621622692
108
2.16530312972741
107
2.16531004322789
109
2.16531695672838
120
2.16532387022887
97
2.16533078372936
99
2.16533769722984
103
2.16534461073033
115
2.16535152423082
110
2.16535843773131
101
2.16536535123179
112
2.16537226473228
121
2.16537917823277
110
2.16538609173326
95
2.16539300523374
110
2.16539991873423
118
2.16540683223472
104
2.16541374573521
113
2.1654206592357
107
2.16542757273618
124
2.16543448623667
105
2.16544139973716
110
2.16544831323765
99
2.16545522673813
103
2.16546214023862
124
2.16546905373911
118
2.1654759672396
91
2.16548288074008
109
2.16548979424057
106
2.16549670774106
106
2.16550362124155
108
2.16551053474203
121
2.16551744824252
115
2.16552436174301
101
2.1655312752435
100
2.16553818874398
104
2.16554510224447
104
2.16555201574496
118
2.16555892924545
104
2.16556584274593
106
2.16557275624642
120
2.16557966974691
115
2.1655865832474
114
2.16559349674788
119
2.16560041024837
109
2.16560732374886
109
2.16561423724935
112
2.16562115074983
100
2.16562806425032
111
2.16563497775081
106
2.1656418912513
116
2.16564880475178
113
2.16565571825227
99
2.16566263175276
114
2.16566954525325
104
2.16567645875373
106
2.16568337225422
106
2.16569028575471
105
2.1656971992552
104
2.16570411275568
106
2.16571102625617
107
2.16571793975666
110
2.16572485325715
105
2.16573176675763
101
2.16573868025812
113
2.16574559375861
106
2.1657525072591
91
2.16575942075958
119
2.16576633426007
115
2.16577324776056
97
2.16578016126105
116
2.16578707476153
112
2.16579398826202
110
2.16580090176251
112
2.165807815263
125
2.16581472876348
107
2.16582164226397
102
2.16582855576446
107
2.16583546926495
108
2.16584238276543
110
2.16584929626592
111
2.16585620976641
124
2.1658631232669
123
2.16587003676738
105
2.16587695026787
100
2.16588386376836
114
2.16589077726885
112
2.16589769076933
110
2.16590460426982
108
2.16591151777031
122
2.1659184312708
121
2.16592534477128
101
2.16593225827177
108
2.16593917177226
119
2.16594608527275
110
2.16595299877323
113
2.16595991227372
110
2.16596682577421
104
2.1659737392747
125
2.16598065277518
116
2.16598756627567
117
2.16599447977616
112
2.16600139327665
119
2.16600830677713
114
2.16601522027762
108
2.16602213377811
114
2.1660290472786
109
2.16603596077908
117
2.16604287427957
111
2.16604978778006
108
2.16605554455782
114
2.16606117281082
115
2.16606680106383
121
2.16607242931684
114
2.16607805756985
119
2.16608368582286
112
2.16608931407587
116
2.16609494232887
106
2.16610057058188
115
2.16610619883489
110
2.1661118270879
112
2.16611745534091
110
2.16612308359392
100
2.16612871184693
113
2.16613434009993
110
2.16613996835294
105
2.16614559660595
114
2.16615122485896
87
2.16615685311197
108
2.16616248136498
107
2.16616810961798
123
2.16617373787099
122
2.166179366124
111
2.16618499437701
121
2.16619062263002
107
2.16619625088303
121
2.16620187913603
108
2.16620750738904
124
2.16621313564205
112
2.16621876389506
96
2.16622439214807
105
2.16623002040108
109
2.16623564865408
118
2.16624127690709
104
2.1662469051601
107
2.16625253341311
100
2.16625816166612
104
2.16626378991913
108
2.16626941817213
101
2.16627504642514
120
2.16628067467815
107
2.16628630293116
108
2.16629193118417
100
2.16629755943718
114
2.16630318769018
118
2.16630881594319
105
2.1663144441962
102
2.16632007244921
107
2.16632570070222
113
2.16633132895523
117
2.16633695720824
106
2.16634258546124
97
2.16634821371425
104
2.16635384196726
92
2.16635947022027
100
2.16636509847328
96
2.16637072672629
117
2.16637635497929
103
2.1663819832323
101
2.16638761148531
98
2.16639323973832
101
2.16639886799133
110
2.16640449624434
102
2.16641012449734
109
2.16641575275035
129
2.16642138100336
130
2.16642700925637
121
2.16643263750938
118
2.16643826576239
110
2.16644389401539
121
2.1664495222684
111
2.16645515052141
120
2.16646077877442
106
2.16646640702743
100
2.16647203528044
107
2.16647766353345
96
2.16648329178645
107
2.16648892003946
120
2.16649454829247
123
2.16650017654548
121
2.16650580479849
118
2.1665114330515
104
2.1665170613045
96
2.16652268955751
102
2.16652831781052
115
2.16653394606353
113
2.16653957431654
103
2.16654520256955
105
2.16655083082255
121
2.16655645907556
116
2.16656208732857
105
2.16656771558158
106
2.16657334383459
112
2.1665789720876
116
2.1665846003406
115
2.16659022859361
110
2.16659585684662
117
2.16660148509963
121
2.16660711335264
117
2.16661274160565
103
2.16661836985866
113
2.16662399811166
122
2.16662962636467
124
2.16663525461768
113
2.16664088287069
115
2.1666465111237
115
2.16665213937671
119
2.16665776762971
113
2.16666339588272
110
2.16666902413573
103
2.16667465238874
122
2.16668028064175
116
2.16668590889476
99
2.16669153714776
99
2.16669716540077
118
2.16670279365378
113
2.16670842190679
114
2.1667140501598
111
2.16671967841281
137
2.16672530666581
119
2.16673093491882
128
2.16673656317183
127
2.16674219142484
123
2.16674781967785
107
2.16675344793086
116
2.16675907618386
126
2.16676470443687
115
2.16677033268988
112
2.16677596094289
120
2.1667815891959
127
2.16678721744891
114
2.16679284570191
99
2.16679847395492
111
2.16680410220793
119
2.16680973046094
111
2.16681535871395
114
2.16682098696696
120
2.16682661521997
126
2.16683224347297
128
2.16683787172598
114
2.16684349997899
116
2.166849128232
112
2.16685475648501
105
2.16686038473802
104
2.16686601299102
115
2.16687164124403
111
2.16687726949704
110
2.16688289775005
111
2.16688852600306
110
2.16689415425607
100
2.16689978250907
106
2.16690541076208
125
2.16691103901509
127
2.1669166672681
111
2.16692229552111
107
2.16692792377412
114
2.16693355202712
133
2.16693918028013
122
2.16694480853314
109
2.16695043678615
106
2.16695606503916
96
2.16696169329217
91
2.16696732154518
103
2.16697294979818
111
2.16697857805119
117
2.1669842063042
113
2.16698983455721
116
2.16699546281022
109
2.16700109106323
108
2.16700671931623
102
2.16701234756924
111
2.16701797582225
120
2.16702360407526
103
2.16702923232827
106
2.16703486058128
104
2.16704048883428
112
2.16704611708729
101
2.1670517453403
123
2.16705737359331
122
2.16706300184632
109
2.16706863009933
96
2.16707425835233
123
2.16707988660534
107
2.16708551485835
100
2.16709114311136
110
2.16709677136437
113
2.16710239961738
98
2.16710802787038
93
2.16711365612339
118
2.1671192843764
111
2.16712491262941
119
2.16713054088242
120
2.16713616913543
108
2.16714179738844
115
2.16714742564144
125
2.16715305389445
108
2.16715868214746
121
2.16716431040047
144
2.16716993865348
122
2.16717556690649
112
2.16718119515949
99
2.1671868234125
115
2.16719245166551
97
2.16719807991852
88
2.16720370817153
112
2.16720933642454
115
2.16721496467754
97
2.16722059293055
111
2.16722622118356
113
2.16723184943657
109
2.16723747768958
123
2.16724310594259
134
2.16724873419559
117
2.1672543624486
118
2.16725999070161
127
2.16726561895462
127
2.16727124720763
115
2.16727687546064
100
2.16728250371364
90
2.16728813196665
97
2.16729376021966
111
2.16729938847267
112
2.16730501672568
108
2.16731064497869
119
2.1673162732317
121
2.1673219014847
111
2.16732752973771
113
2.16733315799072
115
2.16733878624373
109
2.16734441449674
98
2.16735004274975
112
2.16735567100275
122
2.16736129925576
114
2.16736692750877
114
2.16737255576178
116
2.16737818401479
116
2.1673838122678
124
2.1673894405208
111
2.16739506877381
110
2.16740069702682
129
2.16740632527983
102
2.16741195353284
112
2.16741758178585
101
2.16742321003885
104
2.16742883829186
113
2.16743446654487
116
2.16744009479788
112
2.16744572305089
104
2.1674513513039
99
2.16745697955691
111
2.16746260780991
109
2.16746823606292
111
2.16747386431593
120
2.16747949256894
136
2.16748512082195
132
2.16749074907496
104
2.16749637732796
108
2.16750200558097
109
2.16750763383398
91
2.16751326208699
98
2.16751889034
111
2.16752451859301
135
2.16753014684601
130
2.16753577509902
122
2.16754140335203
124
2.16754703160504
109
2.16755265985805
131
2.16755828811106
117
2.16756391636406
110
2.16756954461707
123
2.16757517287008
113
2.16758080112309
110
2.1675864293761
114
2.16759205762911
115
2.16759768588211
117
2.16760331413512
117
2.16760894238813
98
2.16761457064114
116
2.16762019889415
95
2.16762582714716
113
2.16763145540017
119
2.16763708365317
117
2.16764271190618
111
2.16764834015919
112
2.1676539684122
111
2.16765959666521
118
2.16766522491822
119
2.16767085317122
126
2.16767648142423
122
2.16768210967724
107
2.16768773793025
103
2.16769336618326
109
2.16769899443627
117
2.16770462268927
118
2.16771025094228
100
2.16771587919529
98
2.1677215074483
121
2.16772713570131
105
2.16773276395432
104
2.16773839220732
104
2.16774402046033
110
2.16774964871334
103
2.16775527696635
110
2.16776090521936
113
2.16776653347237
104
2.16777216172537
118
2.16777778997838
117
2.16778341823139
121
2.1677890464844
116
2.16779467473741
113
2.16780030299042
112
2.16780593124343
118
2.16781155949643
109
2.16781718774944
123
2.16782281600245
128
2.16782844425546
129
2.16783407250847
131
2.16783970076148
124
2.16784532901448
118
2.16785095726749
98
2.1678565855205
115
2.16786221377351
108
2.16786784202652
114
2.16787347027953
115
2.16787909853253
110
2.16788472678554
122
2.16789035503855
113
2.16789598329156
110
2.16790161154457
120
2.16790723979758
117
2.16791286805058
111
2.16791849630359
111
2.1679241245566
110
2.16792975280961
117
2.16793538106262
130
2.16794100931563
141
2.16794663756863
112
2.16795226582164
101
2.16795789407465
113
2.16796352232766
122
2.16796915058067
100
2.16797477883368
96
2.16798040708669
124
2.16798603533969
114
2.1679916635927
114
2.16799729184571
107
2.16800292009872
103
2.16800854835173
111
2.16801417660474
118
2.16801980485774
101
2.16802543311075
110
2.16803106136376
101
2.16803668961677
94
2.16804231786978
97
2.16804794612279
110
2.16805357437579
116
2.1680592026288
116
2.16806483088181
115
2.16807045913482
100
2.16807608738783
117
2.16808171564084
123
2.16808734389384
107
2.16809297214685
120
2.16809860039986
105
2.16810422865287
107
2.16810985690588
102
2.16811548515889
O 1s
Ni-W
2020
8
27
14
22
28
7
39
Creation
Created by : 600-72-HP\600-72
Date created : 27/08/2020 14:22
Computer : 600-72-HP
Location
Location ID : 0-150W
Sample : Ni-W
Description : (21.195,11.291,0.905)mm
Tilt : 0.00
Charge Neutraliser : On
Filament Current : 0.45A
Filament Bias : 1V
Charge Balance : 4V
Settings
Excitation
Mode : XPS - monochromatic
Tuning : Spectroscopy
Emission current : 15.00mA
Anode library : Al
ESCA modes
Collimation : Slot
Lens : Hybrid
Resolution : 20.00
Scan
Deflection : (0.000, 0.000)mm
O 1s : 941.690-966.690eV, Sweeps 5
Start : 941.690eV
End : 966.690eV
Centre : 954.190eV
Width : 25.000eV
Step size : 0.100eV
Number Steps : 250
Dwell time : 239ms
Sweep time : 60s
Sweeps : 5
Instrument Conditions
Work function : -4.50
Acquisition Conditions
X-ray Power : 225.00W
XPS
3
21.19525
11.290625
0.905375
Al (mono)
1486.69
225
1E+37
1E+37
1E+37
1E+37
FAT
20
1E+37
-4.5
1E+37
1E+37
1E+37
1E+37
1E+37
O
1s
-1
Kinetic energy
eV
941.69
0.1
2
Intensity
d
Transmission
d
pulse counting
0.239043
5
0
1E+37
1E+37
1E+37
0
502
1268
5166
2.16761917009364
2.16796441289868
1620
2.16796441289868
1707
2.16796303192746
1672
2.16796165095624
1648
2.16796026998502
1606
2.1679588890138
1709
2.16795750804258
1737
2.16795612707136
1691
2.16795474610014
1736
2.16795336512892
1706
2.1679519841577
1762
2.16795060318648
1747
2.16794922221526
1624
2.16794784124404
1619
2.16794646027282
1708
2.1679450793016
1710
2.16794369833038
1649
2.16794231735916
1695
2.16794093638794
1668
2.16793955541672
1623
2.1679381744455
1697
2.16793679347428
1660
2.16793541250306
1707
2.16793403153184
1760
2.16793265056062
1727
2.1679312695894
1642
2.16792988861818
1657
2.16792850764696
1720
2.16792712667574
1717
2.16792574570452
1718
2.1679243647333
1696
2.16792298376208
1699
2.16792160279086
1655
2.16792022181964
1709
2.16791884084842
1699
2.1679174598772
1646
2.16791607890598
1685
2.16791469793476
1686
2.16791331696354
1675
2.16791193599232
1674
2.1679105550211
1656
2.16790917404988
1728
2.16790779307866
1666
2.16790641210744
1674
2.16790503113622
1697
2.167903650165
1623
2.16790226919378
1639
2.16790088822256
1614
2.16789950725134
1619
2.16789812628012
1637
2.1678967453089
1665
2.16789536433768
1612
2.16789398336646
1630
2.16789260239524
1604
2.16789122142402
1655
2.1678898404528
1616
2.16788845948158
1593
2.16788707851036
1554
2.16788569753914
1556
2.16788431656791
1542
2.16788293559669
1597
2.16788155462547
1548
2.16788017365425
1585
2.16787879268303
1588
2.16787741171181
1542
2.16787603074059
1565
2.16787464976937
1536
2.16787326879815
1526
2.16787188782693
1511
2.16787050685571
1611
2.16786912588449
1572
2.16786774491327
1544
2.16786636394205
1556
2.16786498297083
1586
2.16786360199961
1502
2.16786222102839
1478
2.16786084005717
1457
2.16785945908595
1559
2.16785807811473
1572
2.16785669714351
1580
2.16785531617229
1571
2.16785393520107
1512
2.16785255422985
1494
2.16785117325863
1519
2.16784979228741
1546
2.16784841131619
1540
2.16784703034497
1518
2.16784564937375
1564
2.16784426840253
1536
2.16784288743131
1540
2.16784150646009
1517
2.16784012548887
1535
2.16783874451765
1548
2.16783736354643
1544
2.16783598257521
1547
2.16783460160399
1530
2.16783322063277
1490
2.16783183966155
1476
2.16783045869033
1521
2.16782907771911
1549
2.16782769674789
1550
2.16782631577667
1543
2.16782493480545
1555
2.16782355383423
1512
2.16782217286301
1498
2.16782079189179
1502
2.16781941092057
1559
2.16781802994935
1491
2.16781664897813
1495
2.16781526800691
1471
2.16781388703569
1467
2.16781250606447
1530
2.16781112509325
1469
2.16780974412203
1475
2.16780836315081
1516
2.16780698217959
1468
2.16780560120837
1477
2.16780422023715
1477
2.16780283926592
1500
2.1678014582947
1444
2.16780007732348
1419
2.16779869635226
1444
2.16779731538104
1470
2.16779593440982
1423
2.1677945534386
1483
2.16779317246738
1420
2.16779179149616
1455
2.16779041052494
1443
2.16778902955372
1413
2.1677876485825
1448
2.16778626761128
1480
2.16778488664006
1474
2.16778350566884
1469
2.16778212469762
1511
2.1677807437264
1460
2.16777936275518
1496
2.16777798178396
1529
2.16777660081274
1542
2.16777521984152
1522
2.1677738388703
1539
2.16777245789908
1598
2.16777107692786
1684
2.16776969595664
1671
2.16776831498542
1732
2.1677669340142
1809
2.16776555304298
1851
2.16776417207176
1958
2.16776279110054
2044
2.16776141012932
2056
2.1677600291581
2159
2.16775864818688
2245
2.16775726721566
2373
2.16775588624444
2456
2.16775450527322
2632
2.167753124302
2762
2.16775174333078
2921
2.16775036235956
3147
2.16774898138834
3269
2.16774760041712
3596
2.1677462194459
3857
2.16774483847468
4109
2.16774345750346
4526
2.16774207653224
4667
2.16774069556102
4890
2.1677393145898
4998
2.16773793361858
5106
2.16773655264736
5166
2.16773517167614
5050
2.16773379070492
4677
2.1677324097337
4423
2.16773102876248
4098
2.16772964779126
3828
2.16772826682004
3518
2.16772688584882
3088
2.1677255048776
2753
2.16772412390638
2496
2.16772274293516
2256
2.16772136196394
2087
2.16771998099272
1891
2.1677186000215
1757
2.16771721905027
1677
2.16771583807905
1598
2.16771445710783
1571
2.16771307613661
1445
2.16771169516539
1405
2.16771031419417
1473
2.16770893322295
1487
2.16770755225173
1412
2.16770617128051
1333
2.16770479030929
1348
2.16770340933807
1334
2.16770202836685
1326
2.16770064739563
1342
2.16769926642441
1316
2.16769788545319
1346
2.16769650448197
1352
2.16769512351075
1319
2.16769374253953
1310
2.16769236156831
1338
2.16769098059709
1322
2.16768959962587
1338
2.16768821865465
1370
2.16768683768343
1353
2.16768545671221
1375
2.16768407574099
1339
2.16768269476977
1328
2.16768131379855
1360
2.16767993282733
1365
2.16767855185611
1352
2.16767717088489
1363
2.16767578991367
1380
2.16767440894245
1303
2.16767302797123
1407
2.16767164700001
1268
2.16767026602879
1309
2.16766888505757
1320
2.16766750408635
1355
2.16766612311513
1313
2.16766474214391
1329
2.16766336117269
1296
2.16766198020147
1378
2.16766059923025
1322
2.16765921825903
1343
2.16765783728781
1333
2.16765645631659
1361
2.16765507534537
1339
2.16765369437415
1317
2.16765231340293
1334
2.16765093243171
1352
2.16764955146049
1339
2.16764817048927
1287
2.16764678951805
1362
2.16764540854683
1384
2.16764402757561
1291
2.16764264660439
1358
2.16764126563317
1295
2.16763988466195
1305
2.16763850369073
1291
2.1676371227195
1384
2.16763574174828
1326
2.16763436077706
1319
2.16763297980584
1320
2.16763159883462
1360
2.1676302178634
1318
2.16762883689218
1336
2.16762745592096
1369
2.16762607494974
1356
2.16762469397852
1337
2.1676233130073
1317
2.16762193203608
1323
2.16762055106486
1315
2.16761917009364
C 1s
Ni-W
2020
8
27
14
22
28
7
39
Creation
Created by : 600-72-HP\600-72
Date created : 27/08/2020 14:22
Computer : 600-72-HP
Location
Location ID : 0-150W
Sample : Ni-W
Description : (21.195,11.291,0.905)mm
Tilt : 0.00
Charge Neutraliser : On
Filament Current : 0.45A
Filament Bias : 1V
Charge Balance : 4V
Settings
Excitation
Mode : XPS - monochromatic
Tuning : Spectroscopy
Emission current : 15.00mA
Anode library : Al
ESCA modes
Collimation : Slot
Lens : Hybrid
Resolution : 20.00
Scan
Deflection : (0.000, 0.000)mm
C 1s : 1186.690-1216.690eV, Sweeps 10
Start : 1186.690eV
End : 1216.690eV
Centre : 1201.690eV
Width : 30.000eV
Step size : 0.100eV
Number Steps : 300
Dwell time : 199ms
Sweep time : 60s
Sweeps : 10
Instrument Conditions
Work function : -4.50
Acquisition Conditions
X-ray Power : 225.00W
XPS
4
21.19525
11.290625
0.905375
Al (mono)
1486.69
225
1E+37
1E+37
1E+37
1E+37
FAT
20
1E+37
-4.5
1E+37
1E+37
1E+37
1E+37
1E+37
C
1s
-1
Kinetic energy
eV
1186.69
0.1
2
Intensity
d
Transmission
d
pulse counting
0.199336
10
0
1E+37
1E+37
1E+37
0
602
1773
2782
2.1032336391655
2.10833355078261
1906
2.10390798702838
1923
2.10388755224465
1875
2.10386711746093
1932
2.10384668267721
1948
2.10382624789348
1883
2.10380581310976
1873
2.10378537832604
1906
2.10376494354231
1892
2.10374450875859
1849
2.10372407397487
1935
2.10370363919114
1951
2.10368320440742
1871
2.10366276962369
1840
2.10364233483997
1853
2.10362190005625
1864
2.10360146527252
1917
2.1035810304888
1906
2.10356059570508
1847
2.10354016092135
1920
2.10351972613763
1930
2.10349929135391
1888
2.10347885657018
1864
2.10345842178646
1881
2.10343798700273
1893
2.10341755221901
1900
2.10339711743529
1902
2.10337668265156
1920
2.10335624786784
1888
2.10333581308412
1845
2.10331537830039
1836
2.10329494351667
1853
2.10327450873294
1886
2.10325407394922
1849
2.1032336391655
1816
2.10324879973203
1818
2.10326791533749
1859
2.10328703094294
1843
2.10330614654839
1886
2.10332526215385
1895
2.1033443777593
1889
2.10336349336475
1896
2.10338260897021
1879
2.10340172457566
1829
2.10342084018111
1825
2.10343995578657
1878
2.10345907139202
1911
2.10347818699747
1870
2.10349730260293
1860
2.10351641820838
1784
2.10353553381383
1856
2.10355464941929
1925
2.10357376502474
1886
2.10359288063019
1866
2.10361199623565
1864
2.1036311118411
1887
2.10365022744655
1810
2.10366934305201
1811
2.10368845865746
1819
2.10370757426291
1823
2.10372668986837
1871
2.10374580547382
1900
2.10376492107927
1824
2.10378403668473
1902
2.10380315229018
1872
2.10382226789563
1873
2.10384138350109
1876
2.10386049910654
1885
2.10387961471199
1882
2.10389873031745
1823
2.1039178459229
1858
2.10393696152835
1871
2.10395607713381
1899
2.10397519273926
1899
2.10399430834471
1773
2.10401342395017
1838
2.10403253955562
1924
2.10405165516107
1890
2.10407077076653
1865
2.10408988637198
1860
2.10410900197743
1850
2.10412811758289
1893
2.10414723318834
1848
2.10416634879379
1858
2.10418546439925
1919
2.1042045800047
1891
2.10422369561015
1841
2.10424281121561
1852
2.10426192682106
1871
2.10428104242651
1908
2.10430015803197
1879
2.10431927363742
1913
2.10433838924287
1943
2.10435750484833
1861
2.10437662045378
1938
2.10439573605923
1923
2.10441485166469
1881
2.10443396727014
1904
2.10445308287559
1917
2.10447219848105
1869
2.1044913140865
1823
2.10451042969195
1816
2.1045295452974
1835
2.10454866090286
1832
2.10456777650831
1851
2.10458689211376
1808
2.10460600771922
1851
2.10462512332467
1853
2.10464423893013
1865
2.10466335453558
1888
2.10468247014103
1898
2.10470158574649
1922
2.10472070135194
1913
2.10473981695739
1935
2.10475893256284
1911
2.1047780481683
1890
2.10479716377375
1957
2.1048162793792
1890
2.10483539498466
1875
2.10485451059011
1959
2.10487362619556
1912
2.10489274180102
1929
2.10491185740647
1907
2.10493097301192
1876
2.10495008861738
1882
2.10496920422283
1947
2.10498831982828
1941
2.10500743543374
1931
2.10502655103919
1949
2.10504566664464
1899
2.1050647822501
1999
2.10508389785555
1930
2.105103013461
1949
2.10512212906646
2034
2.10514124467191
2018
2.10516036027736
1987
2.10517947588282
1951
2.10519859148827
1918
2.10521770709372
2046
2.10523682269918
1979
2.10525593830463
1922
2.10527505391008
1918
2.10529416951554
1987
2.10531328512099
1988
2.10533240072644
1891
2.1053515163319
1976
2.10537063193735
1955
2.1053897475428
1945
2.10540886314826
1956
2.10542797875371
1956
2.10544709435916
1954
2.10546620996462
1984
2.10548532557007
1965
2.10550444117552
2002
2.10552355678098
1988
2.10554267238643
2057
2.10556178799188
2063
2.10558090359734
2090
2.10560001920279
2072
2.10561913480824
2103
2.1056382504137
2085
2.10565736601915
2116
2.1056764816246
2157
2.10569559723006
2166
2.10571471283551
2223
2.10573382844096
2211
2.10575294404642
2210
2.10577205965187
2326
2.10579117525732
2310
2.10581029086278
2377
2.10582940646823
2492
2.10584852207368
2494
2.10586763767914
2667
2.10588675328459
2657
2.10590586889004
2745
2.1059249844955
2782
2.10594410010095
2717
2.1059632157064
2760
2.10598233131186
2731
2.10600144691731
2780
2.10602056252276
2733
2.10603967812822
2669
2.10605879373367
2577
2.10607790933912
2436
2.10609702494458
2379
2.10611614055003
2302
2.10613525615548
2246
2.10615437176094
2210
2.10617348736639
2129
2.10619260297184
2017
2.1062117185773
2023
2.10623083418275
1980
2.1062499497882
1991
2.10626906539366
1902
2.10628818099911
1825
2.10630729660456
1871
2.10632641221002
1853
2.10634552781547
1832
2.10636464342092
1854
2.10638375902638
1895
2.10640287463183
1903
2.10642199023728
1926
2.10644110584274
1913
2.10646022144819
1842
2.10647933705364
1911
2.1064984526591
1931
2.10651756826455
1909
2.10653668387
1841
2.10655579947546
1817
2.10657491508091
1884
2.10659403068636
1891
2.10661314629182
1837
2.10663226189727
1825
2.10665137750272
1848
2.10667049310818
1856
2.10668960871363
1784
2.10670872431908
1916
2.10672783992454
1896
2.10674695552999
1927
2.10676607113544
1871
2.1067851867409
1880
2.10680430234635
1819
2.1068234179518
1824
2.10684253355726
1852
2.10686164916271
1913
2.10688076476816
1845
2.10689988037362
1891
2.10691899597907
1848
2.10693811158452
1888
2.10695722718998
1841
2.10697634279543
1951
2.10699545840088
1886
2.10701457400634
1886
2.10703368961179
1896
2.10705280521724
1857
2.1070719208227
1930
2.10709103642815
1888
2.1071101520336
1886
2.10712926763906
1905
2.10714838324451
1837
2.10716749884996
1831
2.10718661445542
1890
2.10720573006087
1875
2.10722484566632
1884
2.10724396127178
1918
2.10726307687723
1909
2.10728219248268
1894
2.10730130808814
1865
2.10732042369359
1900
2.10733953929904
1882
2.1073586549045
1851
2.10737777050995
1905
2.1073968861154
1856
2.10741600172086
1945
2.10743511732631
1963
2.10745423293176
1952
2.10747334853722
2009
2.10749246414267
1903
2.10751157974812
1872
2.10753069535358
1871
2.10754981095903
1889
2.10756892656448
1882
2.10758804216994
1899
2.10760715777539
1909
2.10762627338084
1897
2.1076453889863
1879
2.10766450459175
1842
2.1076836201972
1850
2.10770273580266
1906
2.10772185140811
1857
2.10774096701356
1843
2.10776008261902
1871
2.10777919822447
1913
2.10779831382992
1908
2.10781742943538
1882
2.10783654504083
1848
2.10785566064628
1890
2.10787477625174
1851
2.10789389185719
1905
2.10791300746264
1897
2.1079321230681
1868
2.10795123867355
1877
2.107970354279
1903
2.10798946988445
1896
2.10800858548991
1823
2.10802770109536
1854
2.10804681670081
1845
2.10806593230627
1846
2.10808504791172
1860
2.10810416351717
1894
2.10812327912263
1823
2.10814239472808
1818
2.10816151033353
1843
2.10818062593899
1846
2.10819974154444
1869
2.1082188571499
1840
2.10823797275535
1890
2.1082570883608
1855
2.10827620396625
1825
2.10829531957171
1846
2.10831443517716
1820
2.10833355078261
W 4f
Ni-W
2020
8
27
14
22
28
7
39
Creation
Created by : 600-72-HP\600-72
Date created : 27/08/2020 14:22
Computer : 600-72-HP
Location
Location ID : 0-150W
Sample : Ni-W
Description : (21.195,11.291,0.905)mm
Tilt : 0.00
Charge Neutraliser : On
Filament Current : 0.45A
Filament Bias : 1V
Charge Balance : 4V
Settings
Excitation
Mode : XPS - monochromatic
Tuning : Spectroscopy
Emission current : 15.00mA
Anode library : Al
ESCA modes
Collimation : Slot
Lens : Hybrid
Resolution : 20.00
Scan
Deflection : (0.000, 0.000)mm
W 4f : 1436.690-1461.690eV, Sweeps 10
Start : 1436.690eV
End : 1461.690eV
Centre : 1449.190eV
Width : 25.000eV
Step size : 0.100eV
Number Steps : 250
Dwell time : 239ms
Sweep time : 60s
Sweeps : 10
Instrument Conditions
Work function : -4.50
Acquisition Conditions
X-ray Power : 225.00W
XPS
5
21.19525
11.290625
0.905375
Al (mono)
1486.69
225
1E+37
1E+37
1E+37
1E+37
FAT
20
1E+37
-4.5
1E+37
1E+37
1E+37
1E+37
1E+37
W
4f
-1
Kinetic energy
eV
1436.69
0.1
2
Intensity
d
Transmission
d
pulse counting
0.239044
10
0
1E+37
1E+37
1E+37
0
502
78
5360
1.91094520328784
1.93082618511009
897
1.93082618511009
861
1.93074666118281
922
1.93066713725552
910
1.93058761332823
844
1.93050808940094
872
1.93042856547365
855
1.93034904154636
883
1.93026951761907
845
1.93018999369178
846
1.93011046976449
834
1.9300309458372
824
1.92995142190992
863
1.92987189798263
824
1.92979237405534
785
1.92971285012805
827
1.92963332620076
817
1.92955380227347
801
1.92947427834618
799
1.92939475441889
799
1.9293152304916
750
1.92923570656431
735
1.92915618263702
734
1.92907665870974
757
1.92899713478245
701
1.92891761085516
687
1.92883808692787
694
1.92875856300058
708
1.92867903907329
709
1.928599515146
656
1.92851999121871
659
1.92844046729142
682
1.92836094336413
664
1.92828141943685
632
1.92820189550956
634
1.92812237158227
638
1.92804284765498
612
1.92796332372769
643
1.9278837998004
580
1.92780427587311
619
1.92772475194582
606
1.92764522801853
583
1.92756570409124
578
1.92748618016396
562
1.92740665623667
600
1.92732713230938
567
1.92724760838209
582
1.9271680844548
579
1.92708856052751
548
1.92700903660022
559
1.92692951267293
566
1.92684998874564
543
1.92677046481835
536
1.92669094089106
550
1.92661141696378
533
1.92653189303649
543
1.9264523691092
517
1.92637284518191
549
1.92629332125462
523
1.92621379732733
533
1.92613427340004
487
1.92605474947275
501
1.92597522554546
521
1.92589570161817
528
1.92581617769089
571
1.9257366537636
533
1.92565712983631
536
1.92557760590902
510
1.92549808198173
525
1.92541855805444
553
1.92533903412715
520
1.92525951019986
540
1.92517998627257
555
1.92510046234528
565
1.925020938418
529
1.92494141449071
537
1.92486189056342
539
1.92478236663613
513
1.92470284270884
525
1.92462331878155
560
1.92454379485426
566
1.92446427092697
530
1.92438474699968
539
1.92430522307239
594
1.9242256991451
617
1.92414617521782
574
1.92406665129053
574
1.92398712736324
574
1.92390760343595
587
1.92382807950866
595
1.92374855558137
597
1.92366903165408
596
1.92358950772679
579
1.9235099837995
578
1.92343045987221
622
1.92335093594493
655
1.92327141201764
680
1.92319188809035
638
1.92311236416306
661
1.92303284023577
711
1.92295331630848
655
1.92287379238119
660
1.9227942684539
715
1.92271474452661
710
1.92263522059932
727
1.92255569667203
762
1.92247617274475
721
1.92239664881746
744
1.92231712489017
782
1.92223760096288
738
1.92215807703559
733
1.9220785531083
702
1.92199902918101
721
1.92191950525372
692
1.92183998132643
613
1.92176045739914
604
1.92168093347186
617
1.92160140954457
598
1.92152188561728
568
1.92144236168999
543
1.9213628377627
529
1.92128331383541
477
1.92120378990812
491
1.92112426598083
475
1.92104474205354
465
1.92096521812625
481
1.92088569419897
480
1.92080617027168
522
1.92072664634439
570
1.9206471224171
609
1.92056759848981
619
1.92048807456252
755
1.92040855063523
916
1.92032902670794
1064
1.92024950278065
1247
1.92016997885336
1574
1.92009045492607
1805
1.92001093099879
2178
1.9199314070715
2678
1.91985188314421
3140
1.91977235921692
3475
1.91969283528963
3995
1.91961331136234
4178
1.91953378743505
4381
1.91945426350776
4275
1.91937473958047
4125
1.91929521565318
3852
1.9192156917259
3340
1.91913616779861
2832
1.91905664387132
2370
1.91897711994403
1996
1.91889759601674
1711
1.91881807208945
1545
1.91873854816216
1461
1.91865902423487
1537
1.91857950030758
1645
1.91849997638029
1915
1.91842045245301
2235
1.91834092852572
2604
1.91826140459843
3103
1.91818188067114
3632
1.91810235674385
4277
1.91802283281656
4724
1.91794330888927
5174
1.91786378496198
5360
1.91778426103469
5359
1.9177047371074
5216
1.91762521318011
4828
1.91754568925283
4228
1.91746616532554
3599
1.91738664139825
3047
1.91730711747096
2402
1.91722759354367
1812
1.91714806961638
1345
1.91706854568909
1055
1.9169890217618
821
1.91690949783451
625
1.91682997390722
461
1.91675044997994
398
1.91667092605265
325
1.91659140212536
247
1.91651187819807
212
1.91643235427078
186
1.91635283034349
154
1.9162733064162
159
1.91619378248891
140
1.91611425856162
131
1.91603473463433
129
1.91595521070704
120
1.91587568677976
119
1.91579616285247
114
1.91571663892518
101
1.91563711499789
110
1.9155575910706
119
1.91547806714331
117
1.91539854321602
96
1.91531901928873
88
1.91523949536144
95
1.91515997143415
93
1.91508044750687
115
1.91500092357958
124
1.91492139965229
102
1.914841875725
92
1.91476235179771
95
1.91468282787042
103
1.91460330394313
104
1.91452378001584
116
1.91444425608855
108
1.91436473216126
87
1.91428520823398
97
1.91420568430669
109
1.9141261603794
86
1.91404663645211
91
1.91396711252482
102
1.91388758859753
91
1.91380806467024
97
1.91372854074295
84
1.91364901681566
86
1.91356949288837
105
1.91348996896108
108
1.9134104450338
94
1.91333092110651
99
1.91325139717922
96
1.91317187325193
94
1.91309234932464
120
1.91301282539735
102
1.91293330147006
101
1.91285377754277
78
1.91277425361548
89
1.91269472968819
111
1.91261520576091
101
1.91253568183362
94
1.91245615790633
88
1.91237663397904
102
1.91229711005175
93
1.91221758612446
108
1.91213806219717
97
1.91205853826988
116
1.91197901434259
95
1.9118994904153
101
1.91181996648801
83
1.91174044256073
97
1.91166091863344
106
1.91158139470615
105
1.91150187077886
100
1.91142234685157
95
1.91134282292428
103
1.91126329899699
104
1.9111837750697
104
1.91110425114241
94
1.91102472721512
107
1.91094520328784
end of experiment